Workbook

Sheet 1_DG
A1: Proiectant: SC PLANTERV STUDIO SRL
A2: Adresa: Cristuru Secuiesc, jud. Harghita
A3: Cod Unic de Înregistrare: RO12345678
A4: Numărul de înregistrare: J19/123/2020
A5: DEVIZ GENERAL
A6: al obiectivului de investiții: Extindere fabrică de procesare lapte
A8: Nr. crt. | B8: Denumirea capitolelor și subcapitolelor de cheltuieli | C8: Valoare fără TVA (lei) | D8: TVA (lei) | E8: Valoare cu TVA (lei) | F8: Eligibil (lei) | G8: Neeligibil (lei)
B9: CAPITOLUL 1 Cheltuieli pentru obținerea și amenajarea terenului
A10: 1.1 | B10: Obţinerea terenului | C10: 0 | D10: =ROUND(C10*'0_IG'!$B$10,2) | E10: =ROUND(C10+D10,2) | F10: =C10 | G10: =ROUND(C10-F10,2)
A11: 1.2 | B11: Amenajarea terenului | C11: 85000 | D11: =ROUND(C11*'0_IG'!$B$10,2) | E11: =ROUND(C11+D11,2) | F11: =C11 | G11: =ROUND(C11-F11,2)
A12: 1.3 | B12: Amenajări pentru protecţia mediului și aducerea la starea inițială | C12: 40000 | D12: =ROUND(C12*'0_IG'!$B$10,2) | E12: =ROUND(C12+D12,2) | F12: =C12 | G12: =ROUND(C12-F12,2)
A13: 1.4 | B13: Cheltuieli pentru relocarea/protecția utilităților | C13: 0 | D13: =ROUND(C13*'0_IG'!$B$10,2) | E13: =ROUND(C13+D13,2) | F13: =C13 | G13: =ROUND(C13-F13,2)
B14: Total capitol 1 | C14: =SUM(C10:C13) | D14: =SUM(D10:D13) | E14: =SUM(E10:E13) | F14: =SUM(F10:F13) | G14: =SUM(G10:G13)
B15: CAPITOLUL 2 Cheltuieli pentru asigurarea utilităților necesare obiectivului
A16: 2.1 | B16: Cheltuieli pentru asigurarea utilităților necesare obiectivului | C16: 220000 | D16: =ROUND(C16*'0_IG'!$B$10,2) | E16: =ROUND(C16+D16,2) | F16: =C16 | G16: =ROUND(C16-F16,2)
B17: Total capitol 2 | C17: =SUM(C16:C16) | D17: =SUM(D16:D16) | E17: =SUM(E16:E16) | F17: =SUM(F16:F16) | G17: =SUM(G16:G16)
B18: CAPITOLUL 3 Cheltuieli pentru proiectare și asistență tehnică
A19: 3.1 | B19: Studii (de teren, de fezabilitate) | C19: 35000 | D19: =ROUND(C19*'0_IG'!$B$10,2) | E19: =ROUND(C19+D19,2) | F19: =C19 | G19: =ROUND(C19-F19,2)
A20: 3.2 | B20: Documentații-suport și cheltuieli pentru obținerea de avize, acorduri, autorizații | C20: 0 | D20: =ROUND(C20*'0_IG'!$B$10,2) | E20: =ROUND(C20+D20,2) | F20: =C20 | G20: =ROUND(C20-F20,2)
A21: 3.3 | B21: Expertiză tehnică | C21: 0 | D21: =ROUND(C21*'0_IG'!$B$10,2) | E21: =ROUND(C21+D21,2) | F21: =C21 | G21: =ROUND(C21-F21,2)
A22: 3.4 | B22: Certificarea performanței energetice și auditul energetic al clădirilor | C22: 0 | D22: =ROUND(C22*'0_IG'!$B$10,2) | E22: =ROUND(C22+D22,2) | F22: =C22 | G22: =ROUND(C22-F22,2)
A23: 3.5 | B23: Proiectare (PT + detalii de execuție) | C23: 180000 | D23: =ROUND(C23*'0_IG'!$B$10,2) | E23: =ROUND(C23+D23,2) | F23: =C23 | G23: =ROUND(C23-F23,2)
A24: 3.6 | B24: Organizarea procedurilor de achiziție | C24: 0 | D24: =ROUND(C24*'0_IG'!$B$10,2) | E24: =ROUND(C24+D24,2) | F24: =C24 | G24: =ROUND(C24-F24,2)
A25: 3.7 | B25: Consultanță (management proiect + audit financiar) | C25: 120000 | D25: =ROUND(C25*'0_IG'!$B$10,2) | E25: =ROUND(C25+D25,2) | F25: =C25 | G25: =ROUND(C25-F25,2)
A26: 3.8 | B26: Asistență tehnică (proiectant + dirigenție de șantier) | C26: 0 | D26: =ROUND(C26*'0_IG'!$B$10,2) | E26: =ROUND(C26+D26,2) | F26: =C26 | G26: =ROUND(C26-F26,2)
B27: Total capitol 3 | C27: =SUM(C19:C26) | D27: =SUM(D19:D26) | E27: =SUM(E19:E26) | F27: =SUM(F19:F26) | G27: =SUM(G19:G26)
B28: CAPITOLUL 4 Cheltuieli pentru investiția de bază
A29: 4.1 | B29: Construcții și instalații | C29: ='5_DO1'!C18 | D29: =ROUND(C29*'0_IG'!$B$10,2) | E29: =ROUND(C29+D29,2) | F29: =C29 | G29: =ROUND(C29-F29,2)
A30: 4.2 | B30: Montaj utilaje, echipamente tehnologice și funcționale | C30: ='5_DO1'!C20 | D30: =ROUND(C30*'0_IG'!$B$10,2) | E30: =ROUND(C30+D30,2) | F30: =C30 | G30: =ROUND(C30-F30,2)
A31: 4.3 | B31: Utilaje, echipamente tehnologice și funcționale care necesită montaj | C31: ='5_DO1'!C21 | D31: =ROUND(C31*'0_IG'!$B$10,2) | E31: =ROUND(C31+D31,2) | F31: =C31 | G31: =ROUND(C31-F31,2)
A32: 4.4 | B32: Utilaje, echipamente care nu necesită montaj și echipamente de transport | C32: 0 | D32: =ROUND(C32*'0_IG'!$B$10,2) | E32: =ROUND(C32+D32,2) | F32: =C32 | G32: =ROUND(C32-F32,2)
A33: 4.5 | B33: Dotări | C33: ='5_DO1'!C22 | D33: =ROUND(C33*'0_IG'!$B$10,2) | E33: =ROUND(C33+D33,2) | F33: =C33 | G33: =ROUND(C33-F33,2)
A34: 4.6 | B34: Active necorporale | C34: 60000 | D34: =ROUND(C34*'0_IG'!$B$10,2) | E34: =ROUND(C34+D34,2) | F34: =C34 | G34: =ROUND(C34-F34,2)
B35: Total capitol 4 | C35: =SUM(C29:C34) | D35: =SUM(D29:D34) | E35: =SUM(E29:E34) | F35: =SUM(F29:F34) | G35: =SUM(G29:G34)
B36: CAPITOLUL 5 Alte cheltuieli
A37: 5.1 | B37: Organizare de şantier | C37: 55000 | D37: =ROUND(C37*'0_IG'!$B$10,2) | E37: =ROUND(C37+D37,2) | F37: =C37 | G37: =ROUND(C37-F37,2)
A38: 5.2 | B38: Comisioane, cote, taxe, costul creditului | C38: 38000 | D38: =ROUND(C38*'0_IG'!$B$10,2) | E38: =ROUND(C38+D38,2) | F38: 0 | G38: =ROUND(C38-F38,2)
A39: 5.3 | B39: Cheltuieli diverse şi neprevăzute | C39: 180000 | D39: =ROUND(C39*'0_IG'!$B$10,2) | E39: =ROUND(C39+D39,2) | F39: =C39 | G39: =ROUND(C39-F39,2)
A40: 5.4 | B40: Cheltuieli pentru informare și publicitate | C40: 12000 | D40: =ROUND(C40*'0_IG'!$B$10,2) | E40: =ROUND(C40+D40,2) | F40: =C40 | G40: =ROUND(C40-F40,2)
B41: Total capitol 5 | C41: =SUM(C37:C40) | D41: =SUM(D37:D40) | E41: =SUM(E37:E40) | F41: =SUM(F37:F40) | G41: =SUM(G37:G40)
...

Sheet 0_IG
A1: INFORMAȚII GENERALE PROIECT
A2: Denumire obiectiv: | B2: Extindere fabrică de procesare lapte
A3: Beneficiar: | B3: SC NAPSUGÁR TEJÜZEM SRL
A4: Proiectant: | B4: SC PLANTERV STUDIO SRL
A5: Adresa proiectant: | B5: Cristuru Secuiesc, jud. Harghita
A6: CUI: | B6: RO12345678
A7: Nr. înregistrare: | B7: J19/123/2020
A8: Localitate: | B8: Cristuru Secuiesc, jud. Harghita
A9: Data: | B9: 2026-06-30
A10: Cota TVA: | B10: 0.19
A11: Curs EUR (lei): | B11: 4.97

Sheet 5_DO1
A1: DEVIZUL OBIECTULUI (DO1): Construcții, montaj, utilaje, dotări
A3: Nr. / cod | B3: Obiect / Categorie de lucrări | C3: Valoare fără TVA (lei)
A4: 4.1.1 | B4: Hala de procesare lapte | C4: =SUM(C5:C7)
A5: 4.1.1.1 | B5: Rezistență | C5: 1200000
A6: 4.1.1.2 | B6: Arhitectură | C6: 650000
A7: 4.1.1.3 | B7: Instalații (electrice, sanitare, termice) | C7: 480000
A8: 4.1.2 | B8: Depozit frigorific | C8: =SUM(C9:C11)
A9: 4.1.2.1 | B9: Rezistență | C9: 240000
A10: 4.1.2.2 | B10: Arhitectură (panouri frigorifice) | C10: 90000
A11: 4.1.2.3 | B11: Instalații (electrice, răcire) | C11: 50000
A12: 4.1.3 | B12: Centrală termică | C12: =SUM(C13:C14)
A13: 4.1.3.1 | B13: Construcții | C13: 150000
A14: 4.1.3.2 | B14: Instalații (termice, automatizare) | C14: 120000
A15: 4.1.4 | B15: Amenajări exterioare | C15: =SUM(C16:C16)
A16: 4.1.4.1 | B16: Alei carosabile și platforme betonate | C16: 210000
B18: TOTAL Construcții și instalații (cap. 4.1) | C18: =C4+C8+C12+C15
A20: 4.2 | B20: Montaj utilaje, echipamente | C20: 95000
A21: 4.3 | B21: Utilaje, echipamente tehnologice (cu montaj) | C21: 1850000
A22: 4.5 | B22: Dotări (mobilier laborator, echip. IT) | C22: 240000
