Workbook

Sheet Data
A1: Activity Report
A4: User | B4: Team | C4: Project name | D4: Company name | E4: Task issue ID | F4: Task name | G4: Activity description | H4: Activity date | I4: Start time | J4: End time | K4: Length | L4: Work type
A5: Zoltán Benjámin Zakota | B5: =IF(COUNTIF(Team!$A$2:$A$18,A5)>0,"CPS","") | C5: Synlab SDN | D5: Synlab | E5: 1002406 | F5: SDN-2406 - UK: SA Support (SPS, RM) | G5: JIRAID:110750 | H5: 46113 | K5: 1 | L5: Billable work
A6: Olívia Janka Bernát | B6: =IF(COUNTIF(Team!$A$2:$A$18,A6)>0,"CPS","") | C6: Synlab SDN | D6: Synlab | E6: 1001965 | F6: SDN-1965 - BA task general | G6: JIRAID:110740 follow ups, reviews | H6: 46113 | K6: 1 | L6: Billable work
A7: Marcell Kovács | B7: =IF(COUNTIF(Team!$A$2:$A$18,A7)>0,"CPS","") | C7: Cloud Platform Services | D7: Sonrisa | E7: 193502 | F7: ColosseumDental | H7: 46113 | K7: 4 | L7: Billable work
A8: Ádám Bálint | B8: =IF(COUNTIF(Team!$A$2:$A$18,A8)>0,"CPS","") | C8: Direct Travel Reporting Tool | D8: Direct Travel | F8: FE Dev | G8: DSM(s), NDE-2377, NDE-2457, Chat history takeover | H8: 46113 | K8: 8 | L8: Billable work
A9: Marcell Kovács | B9: =IF(COUNTIF(Team!$A$2:$A$18,A9)>0,"CPS","") | C9: Synlab Plasma (BigCommerce) | D9: Synlab | E9: 8000751 | F9: SD-751 - Create a MongoDB View that can provide BI Team results data requirement | G9: JIRAID:110749 | H9: 46113 | K9: 2.5 | L9: Billable work
A10: Bálint Lajos Török | B10: =IF(COUNTIF(Team!$A$2:$A$18,A10)>0,"CPS","") | C10: Cloud Platform Services | D10: Sonrisa | E10: 197976 | F10: IdomSoft - Faker Microsite Platform | G10: nkfh, VM hozzaferes ellenorzese, piler sync | H10: 46113 | K10: 2 | L10: Billable work
A11: Éva-Henrietta Nagy | B11: =IF(COUNTIF(Team!$A$2:$A$18,A11)>0,"CPS","") | C11: K11 Support | D11: Magyar Államkincstár | E11: 192284 | F11: [#990] Kormányzati szektorba sorolt egyéb szervezetek láthatóságának korlátozása, paraméterezéssel é | G11: + DSM + Heti jegyzetek előkészítése | H11: 46113 | K11: 2 | L11: Billable work
A12: Tibor Zsuró | B12: =IF(COUNTIF(Team!$A$2:$A$18,A12)>0,"CPS","") | C12: Lufthansa Netline - Crew | D12: Lufthansa | F12: General development | H12: 46113 | K12: 8 | L12: Billable work
A13: Péter Oláh | B13: =IF(COUNTIF(Team!$A$2:$A$18,A13)>0,"CPS","") | C13: Diligent Risk Essentials | D13: Diligent | E13: 186318 | F13: QA / Testing | H13: 46113 | K13: 8.5 | L13: Billable work
A14: Norbert Orbán | B14: =IF(COUNTIF(Team!$A$2:$A$18,A14)>0,"CPS","") | C14: SocialBudNewJira | D14: SocialBud | E14: 1003661 | F14: SB-3661 - Prod, UAT, Staging and QA deploy and testing | G14: JIRAID:30749 release/BUGFIX-009 prep | H14: 46113 | K14: 0.5 | L14: Billable work
A15: Attila Kovács | B15: =IF(COUNTIF(Team!$A$2:$A$18,A15)>0,"CPS","") | C15: Jumio AWS | D15: Jumio | E15: 181325 | F15: Development and operations | H15: 46113 | K15: 8 | L15: Billable work
A16: Bálint Lajos Török | B16: =IF(COUNTIF(Team!$A$2:$A$18,A16)>0,"CPS","") | C16: Cloud Platform Services | D16: Sonrisa | E16: 196631 | F16: Diligent - ARC BOS Sunset | G16: cmmc bug fixes, | H16: 46113 | K16: 6 | L16: Billable work
A17: Péter Brindzik | B17: =IF(COUNTIF(Team!$A$2:$A$18,A17)>0,"CPS","") | C17: Consultancy - Observer Service Remap | D17: OBSERVER | E17: 199756 | F17: Modit Knowledge Transfer Meetings | H17: 46113 | K17: 3 | L17: Billable work
A18: István Bánfi | B18: =IF(COUNTIF(Team!$A$2:$A$18,A18)>0,"CPS","") | C18: Consultancy - Observer Service Remap | D18: OBSERVER | E18: 199805 | F18: 3.6.ParlAI API bekötése - UAT | H18: 46113 | K18: 2 | L18: Billable work
A19: Bálint Lajos Török | B19: =IF(COUNTIF(Team!$A$2:$A$18,A19)>0,"CPS","") | C19: CPS Support | D19: Sonrisa | E19: 195325 | F19: MVMI OMNI - general availability collector ticket | H19: 46113 | K19: 6 | L19: Billable work
A20: Viktor Vörös | B20: =IF(COUNTIF(Team!$A$2:$A$18,A20)>0,"CPS","") | C20: K11 Production | D20: Magyar Államkincstár | E20: 198423 | F20: Felhasználó adatainak szerkesztése | H20: 46113 | K20: 1 | L20: Billable work
A21: Péter Brindzik | B21: =IF(COUNTIF(Team!$A$2:$A$18,A21)>0,"CPS","") | C21: Consultancy - Observer Service Remap | D21: OBSERVER | E21: 199755 | F21: Database Migration Plan | H21: 46113 | K21: 2 | L21: Billable work
A22: Dávid Pintér | B22: =IF(COUNTIF(Team!$A$2:$A$18,A22)>0,"CPS","") | C22: Lufthansa - OneRes | D22: Lufthansa | F22: OneRes Development | H22: 46113 | K22: 8 | L22: Billable work
A23: Blanka Cindel | B23: =IF(COUNTIF(Team!$A$2:$A$18,A23)>0,"CPS","") | C23: Sonrisa Office Management | D23: Sonrisa | F23: Insurance Meeting | H23: 46113 | K23: 0.5 | L23: Non-billable work
A24: Levente Gábos | B24: =IF(COUNTIF(Team!$A$2:$A$18,A24)>0,"CPS","") | C24: SocialBudNewJira | D24: SocialBud | E24: 1004630 | F24: SB-4630 - Error occurs when replying to a comment on a published post | G24: JIRAID:31163 | H24: 46113 | K24: 3 | L24: Billable work
A25: Blanka Cindel | B25: =IF(COUNTIF(Team!$A$2:$A$18,A25)>0,"CPS","") | C25: Sonrisa Office Management | D25: Sonrisa | F25: Travel Insurance Management | G25: hó végi lejelentés SRB, MVH travel | H25: 46113 | K25: 0.5 | L25: Non-billable work
A26: Milan Agatonovic | B26: =IF(COUNTIF(Team!$A$2:$A$18,A26)>0,"CPS","") | C26: Consultancy - Observer Service Remap | D26: OBSERVER | E26: 199893 | F26: Regression: The ParlAI hostname from env is not used | H26: 46113 | K26: 0.25 | L26: Billable work
A27: Dániel Kerner | B27: =IF(COUNTIF(Team!$A$2:$A$18,A27)>0,"CPS","") | C27: SAG-NAV | D27: Sagemcom Magyarország Kft. | E27: 200226 | F27: #136519 - ePG- ePénztárgép szoftverfrissítés helyesírási hiba | H27: 46113 | K27: 0.5 | L27: Billable work
A28: Bálint Szente | B28: =IF(COUNTIF(Team!$A$2:$A$18,A28)>0,"CPS","") | C28: KV development | D28: Sonrisa | E28: 199598 | F28: Bug - basic user limitations are not met | G28: exception configs | H28: 46113 | K28: 1 | L28: Non-billable work
A29: Milan Agatonovic | B29: =IF(COUNTIF(Team!$A$2:$A$18,A29)>0,"CPS","") | C29: Consultancy - Observer Service Remap | D29: OBSERVER | E29: 199896 | F29: Read GoogleTranslate settings from env instead of mongodb | H29: 46113 | K29: 0.25 | L29: Billable work
A30: Zoltán Bernátsky | B30: =IF(COUNTIF(Team!$A$2:$A$18,A30)>0,"CPS","") | C30: Diligent BOS sunset | D30: Diligent | E30: 193333 | F30: QA / Testing | H30: 46113 | K30: 8 | L30: Billable work
A31: Levente Gábos | B31: =IF(COUNTIF(Team!$A$2:$A$18,A31)>0,"CPS","") | C31: SocialBudNewJira | D31: SocialBud | E31: 1004592 | F31: SB-4592 - Improve UX with contextual actions for draft posts and generated images | G31: JIRAID:31164 | H31: 46113 | K31: 4.25 | L31: Billable work
A32: Dániel Kerner | B32: =IF(COUNTIF(Team!$A$2:$A$18,A32)>0,"CPS","") | C32: SAG-NAV | D32: Sagemcom Magyarország Kft. | F32: Kódminőség javítás | G32: Teszt üzenetek szűrő bugfix | H32: 46113 | K32: 2 | L32: Billable work
A33: Blanka Cindel | B33: =IF(COUNTIF(Team!$A$2:$A$18,A33)>0,"CPS","") | C33: Sonrisa Office Management | D33: Sonrisa | F33: Site Operation | G33: wc tartály nem működik + óraleolvasások + napi + vízgép szerelővel koordinálás, mert munkaidő után jött | H33: 46113 | K33: 1 | L33: Non-billable work
A34: Milan Agatonovic | B34: =IF(COUNTIF(Team!$A$2:$A$18,A34)>0,"CPS","") | C34: Consultancy - Observer Service Remap | D34: OBSERVER | E34: 199897 | F34: Channel Programmes tab: Table is not rendered correctly on the 1st load | H34: 46113 | K34: 0.5 | L34: Billable work
A35: Bálint Szente | B35: =IF(COUNTIF(Team!$A$2:$A$18,A35)>0,"CPS","") | C35: KV development | D35: Sonrisa | E35: 199576 | F35: Balint KV local rampup | G35: fixing .gitignores and vscode settings.json | H35: 46113 | K35: 1 | L35: Non-billable work
A36: Róbert Benyi | B36: =IF(COUNTIF(Team!$A$2:$A$18,A36)>0,"CPS","") | C36: Diligent Risk Essentials | D36: Diligent | E36: 186319 | F36: Development | H36: 46113 | K36: 8 | L36: Billable work
A37: Milan Agatonovic | B37: =IF(COUNTIF(Team!$A$2:$A$18,A37)>0,"CPS","") | C37: Consultancy - Observer Service Remap | D37: OBSERVER | E37: 199898 | F37: Reindexer reads FRESH_DATA_BOUNDARY from the wrong db | H37: 46113 | K37: 0.25 | L37: Billable work
A38: Sándor-Loránd Nagy | B38: =IF(COUNTIF(Team!$A$2:$A$18,A38)>0,"CPS","") | C38: Boeing 737 | D38: Collinear Group | F38: Project management and administration | G38: Timesheets and administration | H38: 46113 | K38: 2 | L38: Billable work
A39: Gábor Bálint | B39: =IF(COUNTIF(Team!$A$2:$A$18,A39)>0,"CPS","") | C39: Global Blue - Rex - Japan 2026 | D39: Global Blue | F39: Project Management and Administration | H39: 46113 | K39: 2.75 | L39: Billable work
A40: Blanka Cindel | B40: =IF(COUNTIF(Team!$A$2:$A$18,A40)>0,"CPS","") | C40: Sonrisa Office Management | D40: Sonrisa | F40: Asset Management | G40: Vörös Viktor, Tibi | H40: 46113 | K40: 0.5 | L40: Non-billable work
A41: Milan Agatonovic | B41: =IF(COUNTIF(Team!$A$2:$A$18,A41)>0,"CPS","") | C41: Consultancy - Observer Service Remap | D41: OBSERVER | E41: 199899 | F41: Implement configurable lookback time for ES indexer | H41: 46113 | K41: 0.25 | L41: Billable work
A42: Levente Gábos | B42: =IF(COUNTIF(Team!$A$2:$A$18,A42)>0,"CPS","") | C42: SocialBudNewJira | D42: SocialBud | E42: 1003663 | F42: SB-3663 - Meeting participation, meeting preparations, written communication, process updates | G42: JIRAID:31162 DSM | H42: 46113 | K42: 0.25 | L42: Billable work
...

Sheet CPS
A1: User | B1: Team | C1: Project name | D1: Company name | E1: Task issue ID | F1: Task name | G1: Activity description | H1: Activity date | I1: Start time | J1: End time | K1: Length | L1: Work type
A2: Marcell Kovács | B2: CPS | C2: Cloud Platform Services | D2: Sonrisa | E2: 193502 | F2: ColosseumDental | H2: 46113 | K2: 4 | L2: Billable work
A3: Marcell Kovács | B3: CPS | C3: Synlab Plasma (BigCommerce) | D3: Synlab | E3: 8000751 | F3: SD-751 - Create a MongoDB View that can provide BI Team results data requirement | G3: JIRAID:110749 | H3: 46113 | K3: 2.5 | L3: Billable work
A4: Bálint Lajos Török | B4: CPS | C4: Cloud Platform Services | D4: Sonrisa | E4: 197976 | F4: IdomSoft - Faker Microsite Platform | G4: nkfh, VM hozzaferes ellenorzese, piler sync | H4: 46113 | K4: 2 | L4: Billable work
A5: Attila Kovács | B5: CPS | C5: Jumio AWS | D5: Jumio | E5: 181325 | F5: Development and operations | H5: 46113 | K5: 8 | L5: Billable work
A6: Bálint Lajos Török | B6: CPS | C6: Cloud Platform Services | D6: Sonrisa | E6: 196631 | F6: Diligent - ARC BOS Sunset | G6: cmmc bug fixes, | H6: 46113 | K6: 6 | L6: Billable work
A7: István Bánfi | B7: CPS | C7: Consultancy - Observer Service Remap | D7: OBSERVER | E7: 199805 | F7: 3.6.ParlAI API bekötése - UAT | H7: 46113 | K7: 2 | L7: Billable work
A8: Bálint Lajos Török | B8: CPS | C8: CPS Support | D8: Sonrisa | E8: 195325 | F8: MVMI OMNI - general availability collector ticket | H8: 46113 | K8: 6 | L8: Billable work
A9: Andor Szabó | B9: CPS | C9: Cloud Platform Services | D9: Sonrisa | E9: 196631 | F9: Diligent - ARC BOS Sunset | H9: 46113 | K9: 8 | L9: Billable work
A10: István Bánfi | B10: CPS | C10: Idomsoft - Legacy költöztetés | D10: IdomSoft Zrt. | F10: Megbeszélés | H10: 46113 | K10: 2 | L10: Billable work
A11: István Bánfi | B11: CPS | C11: Silver 3.0 | D11: Spinwheel | E11: 1000570 | F11: SIL-570 - Configure CD for deploying freeswitch | H11: 46113 | K11: 1 | L11: Billable work
A12: István Bánfi | B12: CPS | C12: Silver 3.0 | D12: Spinwheel | E12: 1000492 | F12: SIL-492 - SCM: Whisper setup | H12: 46113 | K12: 3 | L12: Billable work
A13: Zsolt Tornai | B13: CPS | C13: NKP-MTR | D13: NKP | E13: 198388 | F13: [SUPPORT] NKP MTR Rendszerek állapotának ellenőrzése - 2026.01.01 - 2026.12.31 közötti időszakban | H13: 46113 | K13: 2 | L13: Billable work
A14: Márk-Ádám Vaida | B14: CPS | C14: Cloud Platform Services | D14: Sonrisa | E14: 189341 | F14: MVMI | G14: Meeting - ONEDC - CI/CD státusz | H14: 46113 | K14: 0.5 | L14: Billable work
A15: Márk-Ádám Vaida | B15: CPS | C15: Cloud Platform Services | D15: Sonrisa | E15: 194703 | F15: Aws Inference Farm | G15: 199861 - Need Decision - Monitoring stack / Langfuse integration | H15: 46113 | K15: 2.5 | L15: Billable work
A16: Márk-Ádám Vaida | B16: CPS | C16: Cloud Platform Services | D16: Sonrisa | E16: 194703 | F16: Aws Inference Farm | G16: 199854 - CleanUp Model Tags from Openwebui | H16: 46113 | K16: 0.25 | L16: Billable work
A17: Márk-Ádám Vaida | B17: CPS | C17: Cloud Platform Services | D17: Sonrisa | E17: 194703 | F17: Aws Inference Farm | G17: 199772 - FutureProof Monitoring | H17: 46113 | K17: 4.75 | L17: Billable work
A18: Zsolt Tornai | B18: CPS | C18: Synlab Plasma (BigCommerce) | D18: Synlab | E18: 8000748 | F18: SD-748 - Azure VPN Gateway SKU Upgrade | G18: JIRAID:113267 | H18: 46113 | K18: 6 | L18: Billable work
A19: Dániel Molnár | B19: CPS | C19: Synlab Plasma (BigCommerce) | D19: Synlab | E19: 8000748 | F19: SD-748 - Azure VPN Gateway SKU Upgrade | G19: JIRAID:113468 | H19: 46113 | K19: 1 | L19: Billable work
A20: Zoltán Szántó | B20: CPS | C20: Cloud Platform Services | D20: Sonrisa | E20: 186697 | F20: Bayer | H20: 46113 | K20: 8 | L20: Billable work
A21: Botond Gáll | B21: CPS | C21: Cloud Platform Services | D21: Sonrisa | E21: 196190 | F21: DirectTravel | G21: qa and prod env | H21: 46113 | K21: 4 | L21: Billable work
A22: Botond Gáll | B22: CPS | C22: Cloud Platform Services | D22: Sonrisa | E22: 193502 | F22: ColosseumDental | G22: Azure tananyag összeállítás | H22: 46113 | K22: 2 | L22: Billable work
A23: Botond Gáll | B23: CPS | C23: Cloud Platform Services | D23: Sonrisa | E23: 190306 | F23: Sontools | G23: logic apps, sonplan mock backend | H23: 46113 | K23: 2 | L23: Billable work
A24: Dániel Molnár | B24: CPS | C24: Cloud Platform Services | D24: Sonrisa | E24: 196190 | F24: DirectTravel | H24: 46113 | K24: 2 | L24: Billable work
A25: Dániel Molnár | B25: CPS | C25: Cloud Platform Services | D25: Sonrisa | E25: 186698 | F25: greeHill | H25: 46113 | K25: 1 | L25: Billable work
A26: Dániel Molnár | B26: CPS | C26: Cloud Platform Services | D26: Sonrisa | E26: 187810 | F26: Meeting | H26: 46113 | K26: 2 | L26: Non-billable work
A27: Dániel Molnár | B27: CPS | C27: Cloud Platform Services | D27: Sonrisa | E27: 193251 | F27: General Research | H27: 46113 | K27: 2 | L27: Billable work
A28: Marcell Kovács | B28: CPS | C28: Cloud Platform Services | D28: Sonrisa | E28: 193502 | F28: ColosseumDental | H28: 46113 | K28: 1.5 | L28: Billable work
A29: Ferenc Beder | B29: CPS | C29: Lufthansa Netline - Crew | D29: Lufthansa | F29: General development | H29: 46113 | K29: 8 | L29: Billable work
A30: Alexandru Ceclan | B30: CPS | C30: Consultancy - Observer Service Remap | D30: OBSERVER | E30: 199612 | F30: 1.6 ES index inicializálás (template) - ES index inicialisation | H30: 46113 | K30: 2 | L30: Billable work
A31: Alexandru Ceclan | B31: CPS | C31: Consultancy - Observer Service Remap | D31: OBSERVER | E31: 199314 | F31: 5.1 ES index feltöltés: Generate Indexes from MongoDB | H31: 46113 | K31: 4 | L31: Billable work
A32: Alexander Póda | B32: CPS | C32: Cloud Platform Services | D32: Sonrisa | E32: 195562 | F32: Observer | G32: sftp-newscliparchive, meetings, | H32: 46113 | K32: 8 | L32: Billable work
A33: Dávid Pap | B33: CPS | C33: Cloud Platform Services | D33: Sonrisa | E33: 196631 | F33: Diligent - ARC BOS Sunset | H33: 46113 | I33: 46113.333 | J33: 46113.667 | K33: 8 | L33: Billable work
A34: Dávid Pap | B34: CPS | C34: CPS Support | D34: Sonrisa | E34: 195325 | F34: MVMI OMNI - general availability collector ticket | H34: 46113 | I34: 46113.917 | J34: 46114 | K34: 2 | L34: Billable work
A35: Marcell Kovács | B35: CPS | C35: Cloud Platform Services | D35: Sonrisa | E35: 193502 | F35: ColosseumDental | H35: 46114 | K35: 8 | L35: Billable work
A36: Bálint Lajos Török | B36: CPS | C36: Cloud Platform Services | D36: Sonrisa | E36: 187810 | F36: Meeting | G36: cps sync | H36: 46114 | K36: 0.5 | L36: Non-billable work
A37: Bálint Lajos Török | B37: CPS | C37: Cloud Platform Services | D37: Sonrisa | E37: 196631 | F37: Diligent - ARC BOS Sunset | G37: test writing for old cisco, Poda Sanyival last few weeks sync meeting | H37: 46114 | K37: 5.5 | L37: Billable work
A38: Andor Szabó | B38: CPS | C38: Cloud Platform Services | D38: Sonrisa | E38: 196631 | F38: Diligent - ARC BOS Sunset | H38: 46114 | K38: 8 | L38: Billable work
A39: Bálint Lajos Török | B39: CPS | C39: Cloud Platform Services | D39: Sonrisa | E39: 189987 | F39: Learning | G39: python test for diligent | H39: 46114 | K39: 2 | L39: Billable work
A40: Attila Kovács | B40: CPS | C40: Jumio AWS | D40: Jumio | E40: 181325 | F40: Development and operations | H40: 46114 | K40: 8 | L40: Billable work
...

Sheet Team
A1: Name | B1: Site | C1: Status | D1: Level | E1: Position
A2: Alexander Póda | B2: BUD | C2: Available | D2: E7 | E2: =IF(D2="E1","Junior", IF(D2="E2","Junior", IF(D2="E3","Expert", IF(D2="E4","Expert", IF(D2="E5","Advanced", IF(D2="E6","Senior", IF(D2="E7","Senior", IF(D2="E8","Lead", IF(D2="E9","Lead","") ) ) ) ) ) ) ) ) -> Senior
A3: Péter Bakonyi | B3: SZEG | C3: Available | D3: E6 | E3: =IF(D3="E1","Junior", IF(D3="E2","Junior", IF(D3="E3","Expert", IF(D3="E4","Expert", IF(D3="E5","Advanced", IF(D3="E6","Senior", IF(D3="E7","Senior", IF(D3="E8","Lead", IF(D3="E9","Lead","") ) ) ) ) ) ) ) ) -> Senior
A4: Gergely Peidl | B4: BUD | C4: Available | D4: E8 | E4: =IF(D4="E1","Junior", IF(D4="E2","Junior", IF(D4="E3","Expert", IF(D4="E4","Expert", IF(D4="E5","Advanced", IF(D4="E6","Senior", IF(D4="E7","Senior", IF(D4="E8","Lead", IF(D4="E9","Lead","") ) ) ) ) ) ) ) ) -> Lead
A5: Alexandru Ceclan | B5: MVH | C5: Available | D5: E8 | E5: =IF(D5="E1","Junior", IF(D5="E2","Junior", IF(D5="E3","Expert", IF(D5="E4","Expert", IF(D5="E5","Advanced", IF(D5="E6","Senior", IF(D5="E7","Senior", IF(D5="E8","Lead", IF(D5="E9","Lead","") ) ) ) ) ) ) ) ) -> Lead
A6: Attila Jankó-Király | B6: PCS | C6: Available | D6: E7 | E6: =IF(D6="E1","Junior", IF(D6="E2","Junior", IF(D6="E3","Expert", IF(D6="E4","Expert", IF(D6="E5","Advanced", IF(D6="E6","Senior", IF(D6="E7","Senior", IF(D6="E8","Lead", IF(D6="E9","Lead","") ) ) ) ) ) ) ) ) -> Senior
A7: Attila Kovács | B7: MVH | C7: Available | D7: E5 | E7: =IF(D7="E1","Junior", IF(D7="E2","Junior", IF(D7="E3","Expert", IF(D7="E4","Expert", IF(D7="E5","Advanced", IF(D7="E6","Senior", IF(D7="E7","Senior", IF(D7="E8","Lead", IF(D7="E9","Lead","") ) ) ) ) ) ) ) ) -> Advanced
A8: Zsolt Tornai | B8: MVH | C8: Available | D8: E4 | E8: =IF(D8="E1","Junior", IF(D8="E2","Junior", IF(D8="E3","Expert", IF(D8="E4","Expert", IF(D8="E5","Advanced", IF(D8="E6","Senior", IF(D8="E7","Senior", IF(D8="E8","Lead", IF(D8="E9","Lead","") ) ) ) ) ) ) ) ) -> Expert
A9: Bálint Lajos Török | B9: MVH | C9: Available | D9: E5 | E9: =IF(D9="E1","Junior", IF(D9="E2","Junior", IF(D9="E3","Expert", IF(D9="E4","Expert", IF(D9="E5","Advanced", IF(D9="E6","Senior", IF(D9="E7","Senior", IF(D9="E8","Lead", IF(D9="E9","Lead","") ) ) ) ) ) ) ) ) -> Advanced
A10: Márk-Ádám Vaida | B10: MVH | C10: Available | D10: E4 | E10: =IF(D10="E1","Junior", IF(D10="E2","Junior", IF(D10="E3","Expert", IF(D10="E4","Expert", IF(D10="E5","Advanced", IF(D10="E6","Senior", IF(D10="E7","Senior", IF(D10="E8","Lead", IF(D10="E9","Lead","") ) ) ) ) ) ) ) ) -> Expert
A11: Dávid Pap | B11: BUD | C11: Available | D11: E1 | E11: =IF(D11="E1","Junior", IF(D11="E2","Junior", IF(D11="E3","Expert", IF(D11="E4","Expert", IF(D11="E5","Advanced", IF(D11="E6","Senior", IF(D11="E7","Senior", IF(D11="E8","Lead", IF(D11="E9","Lead","") ) ) ) ) ) ) ) ) -> Junior
A12: Botond Gáll | B12: MVH | C12: Available | D12: E1 | E12: =IF(D12="E1","Junior", IF(D12="E2","Junior", IF(D12="E3","Expert", IF(D12="E4","Expert", IF(D12="E5","Advanced", IF(D12="E6","Senior", IF(D12="E7","Senior", IF(D12="E8","Lead", IF(D12="E9","Lead","") ) ) ) ) ) ) ) ) -> Junior
A13: Marcell Kovács | B13: BUD | C13: Future | D13: E3 | E13: =IF(D13="E1","Junior", IF(D13="E2","Junior", IF(D13="E3","Expert", IF(D13="E4","Expert", IF(D13="E5","Advanced", IF(D13="E6","Senior", IF(D13="E7","Senior", IF(D13="E8","Lead", IF(D13="E9","Lead","") ) ) ) ) ) ) ) ) -> Expert
A14: Zoltán Szántó | B14: MVH | C14: Future | D14: E8 | E14: =IF(D14="E1","Junior", IF(D14="E2","Junior", IF(D14="E3","Expert", IF(D14="E4","Expert", IF(D14="E5","Advanced", IF(D14="E6","Senior", IF(D14="E7","Senior", IF(D14="E8","Lead", IF(D14="E9","Lead","") ) ) ) ) ) ) ) ) -> Lead
A15: Dániel Molnár | B15: BUD | D15: e8 | E15: =IF(D15="E1","Junior", IF(D15="E2","Junior", IF(D15="E3","Expert", IF(D15="E4","Expert", IF(D15="E5","Advanced", IF(D15="E6","Senior", IF(D15="E7","Senior", IF(D15="E8","Lead", IF(D15="E9","Architect","") ) ) ) ) ) ) ) ) -> Lead
A16: István Bánfi | D16: e9 | E16: Contractor
A17: Ferenc Beder | D17: e7 | E17: PartTime
A18: Andor Szabó | D18: e3 | E18: Contractor

Sheet Sheet2
A2: Company name | B2: Team | C2: Task name | D2: User | E2: Sum of Length
A3: IdomSoft Zrt. | E3: 20
A4: Jumio | E4: 160
A5: Lufthansa | E5: 160
A6: NKP | E6: 2
A7: Sonrisa | B7: CPS | C7: Aws Inference Farm | E7: 23
C8: Bayer | E8: 118.5
C9: ColosseumDental | D9: Botond Gáll | E9: 17
D10: Marcell Kovács | E10: 30.25
D11: Zoltán Szántó | E11: 4
C12: ColosseumDental Total | E12: 51.25
C13: Deutsche Telekom | E13: 1
C14: DevOps Guild activities | E14: 1.5
C15: Diligent - ARC BOS Sunset | E15: 302.5
C16: DirectTravel | E16: 109.5
C17: General Research | E17: 22
C18: greeHill | E18: 220.75
C19: IdomSoft - Faker Microsite Platform | E19: 37.5
C20: Internal Systems | E20: 39
C21: Interviews | E21: 12.75
C22: Learning | E22: 6.25
C23: Meeting | E23: 84.75
C24: MVMI | D24: Bálint Lajos Török | E24: 0.5
D25: Botond Gáll | E25: 0.5
D26: Ferenc Beder | E26: 6
D27: Márk-Ádám Vaida | E27: 20.75
D28: Zoltán Szántó | E28: 6.5
C29: MVMI Total | E29: 34.25
C30: MVMI OMNI - general availability collector ticket | E30: 526
C31: Observer | E31: 234.25
C32: OKFŐ | E32: 10
C33: Onriva: Incidents , New features | E33: 29
C34: Onriva: Availability, Monitoring, Meetings | E34: 66.25
C35: Paid leave | E35: 96
C36: Power automate | E36: 19.5
C37: ProSharp - OTEL | E37: 75.25
C38: SocialBud : Incidents , New features | D38: Marcell Kovács | E38: 6
C39: SocialBud : Incidents , New features Total | E39: 6
C40: SocialBud: Availability, Monitoring, Meetings | D40: Alexander Póda | E40: 1.75
C41: SocialBud: Availability, Monitoring, Meetings Total | E41: 1.75
...

Sheet Sheet1
A2: Company name | B2: User | C2: Task name | D2: Sum of Length
A3: IdomSoft Zrt. | D3: 20
A4: Jumio | D4: 160
A5: Lufthansa | D5: 160
A6: NKP | D6: 2
A7: Sonrisa | B7: Alexander Póda | C7: Aws Inference Farm | D7: 1.5
C8: Diligent - ARC BOS Sunset | D8: 57.75
C9: Internal Systems | D9: 1
C10: Interviews | D10: 4
C11: Meeting | D11: 3.5
C12: Observer | D12: 90.5
C13: SocialBud: Availability, Monitoring, Meetings | D13: 1.75
B14: Alexander Póda Total | D14: 160
B15: Alexandru Ceclan | C15: Aws Inference Farm | D15: 15
C16: Interviews | D16: 3.5
C17: Meeting | D17: 9
C18: Observer | D18: 109
B19: Alexandru Ceclan Total | D19: 136.5
B20: Andor Szabó | C20: Diligent - ARC BOS Sunset | D20: 40
B21: Andor Szabó Total | D21: 40
B22: Bálint Lajos Török | C22: Bayer | D22: 30.5
C23: Diligent - ARC BOS Sunset | D23: 48.5
C24: IdomSoft - Faker Microsite Platform | D24: 37.5
C25: Internal Systems | D25: 5
C26: Interviews | D26: 1
C27: Meeting | D27: 5
C28: MVMI | D28: 0.5
C29: MVMI OMNI - general availability collector ticket | D29: 96
C30: Paid leave | D30: 32
B31: Bálint Lajos Török Total | D31: 256
B32: Botond Gáll | C32: Aws Inference Farm | D32: 1
C33: ColosseumDental | D33: 17
C34: DirectTravel | D34: 60.5
C35: Interviews | D35: 3.25
C36: Meeting | D36: 6.75
C37: MVMI | D37: 0.5
C38: MVMI OMNI - general availability collector ticket | D38: 92
C39: Onriva: Incidents , New features | D39: 6
C40: Onriva: Availability, Monitoring, Meetings | D40: 32
C41: Paid leave | D41: 8
...

Sheet Sheet3
A1: Total hours | B1: (Multiple Items)
A3: User | B3: Sum of Length
A4: Alexander Póda | B4: 160
A5: Alexandru Ceclan | B5: 136.5
A6: Andor Szabó | B6: 40
A7: Attila Kovács | B7: 160
A8: Bálint Lajos Török | B8: 128
A9: Botond Gáll | B9: 150.5
A10: Dániel Molnár | B10: 138
A11: Dávid Pap | B11: 160
A12: Ferenc Beder | B12: 6
A13: István Bánfi | B13: 119.25
A14: Marcell Kovács | B14: 144
A15: Márk-Ádám Vaida | B15: 160
... A19: Grand Total | B19: 1809.75
A22: Internal hours | B22: (Multiple Items) | D22: Internal hours | E22: MVMI OMNI - general availability collector ticket | G22: Internal hours | H22: Paid leave | J22: User | K22: István Bánfi | M22: User | N22: Andor Szabó
A24: User | B24: Sum of Length | D24: User | E24: Sum of Length | G24: User | H24: Sum of Length | J24: Project name | K24: Sum of Length | M24: Project name | N24: Sum of Length
A25: Alexander Póda | B25: 8.5 | D25: Bálint Lajos Török | E25: 96 | G25: Bálint Lajos Török | H25: 32 | J25: Cloud Platform Services | K25: 28.25 | M25: Cloud Platform Services | N25: 40
A26: Alexandru Ceclan | B26: 12.5 | D26: Botond Gáll | E26: 92 | G26: Botond Gáll | H26: 8 | J26: Idomsoft - Legacy költöztetés | K26: 20 | M26: Grand Total | N26: 40
A27: Bálint Lajos Török | B27: 11 | D27: Dávid Pap | E27: 124 | G27: Marcell Kovács | H27: 16 | J27: Silver 3.0 | K27: 73.5
A28: Botond Gáll | B28: 10 | D28: Márk-Ádám Vaida | E28: 118 | G28: Zoltán Szántó | H28: 32 | J28: Sonrisa Presales | K28: 1
A29: Dániel Molnár | B29: 63.5 | D29: Zoltán Szántó | E29: 96 | G29: Zsolt Tornai | H29: 8 | J29: Grand Total | K29: 122.75
A30: Dávid Pap | B30: 3.75 | D30: Grand Total | E30: 526 | G30: Grand Total | H30: 96
A31: István Bánfi | B31: 31.5
A32: Marcell Kovács | B32: 3.25
A33: Márk-Ádám Vaida | B33: 32.75
A34: Péter Bakonyi | B34: 4
A35: Zsolt Tornai | B35: 2
A36: Grand Total | B36: 182.75
